<?xml version="1.0" encoding="utf-8"?>
<robot name="rm65_svh_right">
  <link name="arm_base_link">
    <inertial>
      <origin xyz="-0.000433277303987328 -3.54664423471128E-05 0.0599427668933796" rpy="0 0 0" />
      <mass value="0.841070778135659" />
      <inertia ixx="0.0017261110801622" ixy="2.52746264980217E-06" ixz="-3.67690303614961E-05"
        iyy="0.00170987405835604" iyz="1.67996364994424E-06" izz="0.000904023422915791" />
    </inertial>
    <visual>
      <origin xyz="0 0 0" rpy="0 0 0" />
      <geometry>
        <mesh filename="../meshes/rm65/rm65_base_link.stl" />
      </geometry>
      <material name="">
        <color rgba="1 1 1 1" />
      </material>
    </visual>
    <collision>
      <origin xyz="0 0 0" rpy="0 0 0" />
      <geometry>
        <mesh filename="../meshes/rm65/rm65_base_link.stl" />
      </geometry>
    </collision>
  </link>
  <link name="arm_link1">
    <inertial>
      <origin xyz="1.2226305431569E-08 0.0211079974844683 -0.0251854220842269" rpy="0 0 0" />
      <mass value="0.593563443690403" />
      <inertia ixx="0.00126614120341847" ixy="-1.294980943835E-08" ixz="-9.80120923066996E-09"
        iyy="0.00118168178300364" iyz="-0.00021121727444415" izz="0.00056135241627747" />
    </inertial>
    <visual>
      <origin xyz="0 0 0" rpy="0 0 0" />
      <geometry>
        <mesh filename="../meshes/rm65/rm65_link1.stl" />
      </geometry>
      <material name="">
        <color rgba="1 1 1 1" />
      </material>
    </visual>
    <collision>
      <origin xyz="0 0 0" rpy="0 0 0" />
      <geometry>
        <mesh filename="../meshes/rm65/rm65_link1.stl" />
      </geometry>
    </collision>
  </link>
  <joint name="arm_joint1" type="revolute">
    <origin xyz="0 0 0.2405" rpy="0 0 0" />
    <parent link="arm_base_link" />
    <child link="arm_link1" />
    <axis xyz="0 0 1" />
    <limit lower="-3.1" upper="3.1" effort="60" velocity="3.14" />
  </joint>
  <link name="arm_link2">
    <inertial>
      <origin xyz="0.152256463426163 4.75383656106654E-07 -0.00620260383607792" rpy="0 0 0" />
      <mass value="0.864175046869043" />
      <inertia ixx="0.00089150298478414" ixy="-2.23268489334765E-08" ixz="0.00156246461035015"
        iyy="0.00733754343083901" iyz="6.28110889329165E-09" izz="0.00697869103915473" />
    </inertial>
    <visual>
      <origin xyz="0 0 0" rpy="0 0 0" />
      <geometry>
        <mesh filename="../meshes/rm65/rm65_link2.stl" />
      </geometry>
      <material name="">
        <color rgba="1 1 1 1" />
      </material>
    </visual>
    <collision>
      <origin xyz="0 0 0" rpy="0 0 0" />
      <geometry>
        <mesh filename="../meshes/rm65/rm65_link2.stl" />
      </geometry>
    </collision>
  </link>
  <joint name="arm_joint2" type="revolute">
    <origin xyz="0 0 0" rpy="1.5708 -1.5708 0" />
    <parent link="arm_link1" />
    <child link="arm_link2" />
    <axis xyz="0 0 1" />
    <limit lower="-2.268" upper="2.268" effort="60" velocity="3.14" />
  </joint>
  <link name="arm_link3">
    <inertial>
      <origin xyz="5.05312670989961E-06 -0.0595925663694732 0.010569069212336" rpy="0 0 0" />
      <mass value="0.289633681624654" />
      <inertia ixx="0.00063737100450158" ixy="-7.05261293649751E-08" ixz="-3.86643272239426E-08"
        iyy="0.00015648388095025" iyz="-0.00014461035994916" izz="0.000614178164773085" />
    </inertial>
    <visual>
      <origin xyz="0 0 0" rpy="0 0 0" />
      <geometry>
        <mesh
          filename="../meshes/rm65/rm65_link3.stl" />
      </geometry>
      <material name="">
        <color rgba="1 1 1 1" />
      </material>
    </visual>
    <collision>
      <origin xyz="0 0 0" rpy="0 0 0" />
      <geometry>
        <mesh filename="../meshes/rm65/rm65_link3.stl" />
      </geometry>
    </collision>
  </link>
  <joint name="arm_joint3" type="revolute">
    <origin xyz="0.256 0 0" rpy="0 0 1.5708" />
    <parent link="arm_link2" />
    <child link="arm_link3" />
    <axis xyz="0 0 1" />
    <limit lower="-2.355" upper="2.355" effort="30" velocity="3.92" />
  </joint>
  <link name="arm_link4">
    <inertial>
      <origin xyz="1.15516617405898E-06 -0.0180424468598241 -0.0215394748352687" rpy="0 0 0" />
      <mass value="0.239419768320061" />
      <inertia ixx="0.000285938919722783" ixy="3.07101359163101E-09" ixz="-2.21994118981953E-09"
        iyy="0.000262727540304212" iyz="4.4236583260078E-05" izz="0.000119888082791859" />
    </inertial>
    <visual>
      <origin xyz="0 0 0" rpy="0 0 0" />
      <geometry>
        <mesh filename="../meshes/rm65/rm65_link4.stl" />
      </geometry>
      <material name="">
        <color rgba="1 1 1 1" />
      </material>
    </visual>
    <collision>
      <origin xyz="0 0 0" rpy="0 0 0" />
      <geometry>
        <mesh filename="../meshes/rm65/rm65_link4.stl" />
      </geometry>
    </collision>
  </link>
  <joint name="arm_joint4" type="revolute">
    <origin xyz="0 -0.21 0" rpy="1.5708 0 0" />
    <parent link="arm_link3" />
    <child link="arm_link4" />
    <axis xyz="0 0 1" />
    <limit lower="-3.1" upper="3.1" effort="10" velocity="3.92" />
  </joint>
  <link name="arm_link5">
    <inertial>
      <origin xyz="3.19794786262152E-06 -0.0593808368101458 0.00736804250989326" rpy="0 0 0" />
      <mass value="0.218799761431678" />
      <inertia ixx="0.000350540363914072" ixy="-3.41781619975602E-08" ixz="-1.77056457224373E-08"
        iyy="0.000104927867487581" iyz="-7.82431228461971E-05" izz="0.000334482418423629" />
    </inertial>
    <visual>
      <origin xyz="0 0 0" rpy="0 0 0" />
      <geometry>
        <mesh filename="../meshes/rm65/rm65_link5.stl" />
      </geometry>
      <material name="">
        <color rgba="1 1 1 1" />
      </material>
    </visual>
    <collision>
      <origin xyz="0 0 0" rpy="0 0 0" />
      <geometry>
        <mesh filename="../meshes/rm65/rm65_link5.stl" />
      </geometry>
    </collision>
  </link>
  <joint name="arm_joint5" type="revolute">
    <origin xyz="0 0 0" rpy="-1.5708 0 0" />
    <parent link="arm_link4" />
    <child link="arm_link5" />
    <axis xyz="0 0 1" />
    <limit lower="-2.233" upper="2.233" effort="10" velocity="3.92" />
  </joint>
  <link name="arm_link6">
    <inertial>
      <origin xyz="0.000714234511756999 -0.000396718732824521 -0.0126723660946126" rpy="0 0 0" />
      <mass value="0.0649018034311231" />
      <inertia ixx="2.02766547502765E-05" ixy="-1.32505200276849E-06" ixz="-2.5845091522508E-08"
        iyy="1.87986725225022E-05" iyz="3.39471452125439E-09" izz="3.17885459163081E-05" />
    </inertial>
    <visual>
      <origin xyz="0 0 0" rpy="0 0 0" />
      <geometry>
        <mesh filename="../meshes/rm65/rm65_link6.stl" />
      </geometry>
      <material name="">
        <color rgba="1 1 1 1" />
      </material>
    </visual>
    <collision>
      <origin xyz="0 0 0" rpy="0 0 0" />
      <geometry>
        <mesh filename="../meshes/rm65/rm65_link6.stl" />
      </geometry>
    </collision>
  </link>
  <joint name="arm_joint6" type="revolute">
    <origin xyz="0 -0.144 0" rpy="1.5708 0 0" />
    <parent link="arm_link5" />
    <child link="arm_link6" />
    <axis xyz="0 0 1" />
    <limit lower="-6.28" upper="6.28" effort="10" velocity="3.92" />
  </joint>


  <joint name="arm_hand_joint" type="fixed">
    <parent link="arm_link6" />
    <child link="right_hand_base_link" />
    <origin xyz="0.055 0.002 0.028" rpy="1.57079 0 -1.57079" />
  </joint>



  <link name="right_hand_base_link"/>
  <!--<joint name="root_joint" type="fixed">
    <parent link="base_link"/>
    <child link="right_hand_base_link"/>
    <origin rpy="0 0 -1.57079" xyz="0 0 0"/>
  </joint>-->
  <!--<link name="right_hand_base_link">
    <origin rpy="0 0 0" xyz="0 0 0"/>
    <visual>
      <origin rpy="0 0 0" xyz="0 0 -0.032"/>
      <geometry>
        <mesh filename="../meshes/svh/visual/base10.obj"/>
      </geometry>
    </visual>
    <collision>
      <origin rpy="0 0 0" xyz="0 0 -0.009"/>
      <geometry>
        <cylinder radius="0.045" length="0.045"/>
      </geometry>
    </collision>
  </link>-->
  <!-- LENGTH NOT FOUND IN DATASHEET! GUESSED!!! -->
  <link name="right_hand_e1">
    <visual>
      <origin rpy="0 0 0" xyz="0 0.01313 0"/>
      <geometry>
        <mesh filename="../meshes/svh/visual/h10.obj" scale="1 1 1"/>
      </geometry>
    </visual>
    <collision>
      <origin rpy="0 0 0" xyz="0 0.01313 0.013"/>
      <geometry>
        <box size="0.05 0.05 0.026"/>
      </geometry>
    </collision>
    <collision>
      <origin rpy="0 0 0" xyz="-0.00573 0.0035 0.05747"/>
      <geometry>
        <box size="0.0584 0.038 0.0641"/>
      </geometry>
    </collision>
    <collision>
      <origin rpy="0 0 0" xyz="-0.01 0.0035 0.096"/>
      <geometry>
        <box size="0.042 0.038 0.015"/>
      </geometry>
    </collision>
  </link>
  <!-- LENGTH NOT FOUND IN DATASHEET! GUESSED!!! -->
  <link name="right_hand_e2">
    <visual>
      <origin xyz="-0.0007 0 -0.01002"/>
      <geometry>
        <mesh filename="../meshes/svh/visual/h11.obj" scale="1 1 1"/>
      </geometry>
    </visual>
    <collision>
      <origin rpy="0 0 0" xyz="0.016 0 0.02"/>
      <geometry>
        <box size="0.0246 0.035 0.0564"/>
      </geometry>
    </collision>
    <collision>
      <origin rpy="0 0 0" xyz="0.0032 -0.0083 0.048"/>
      <geometry>
        <box size="0.012 0.018 0.021"/>
      </geometry>
    </collision>
  </link>
  <!-- THUMB LINKS -->
  <link name="right_hand_z">
    <visual>
      <origin xyz="0 0 0.02442"/>
      <geometry>
        <mesh filename="../meshes/svh/visual/d10.obj" scale="1 1 1"/>
      </geometry>
    </visual>
    <collision>
      <origin xyz="0 0 0.02842"/>
      <geometry>
        <box size="0.024 0.0188 0.008"/>
      </geometry>
    </collision>
    <collision>
      <origin xyz="0.0125 0.0 0.04292"/>
      <geometry>
        <box size="0.006 0.024 0.033"/>
      </geometry>
    </collision>
    <collision>
      <origin xyz="-0.0125 0.0 0.04292"/>
      <geometry>
        <box size="0.006 0.024 0.033"/>
      </geometry>
    </collision>
  </link>
  <link name="right_hand_a">
    <visual>
      <geometry>
        <mesh filename="../meshes/svh/visual/d11.obj" scale="1 1 1"/>
      </geometry>
    </visual>
    <collision>
      <geometry>
        <mesh filename="../meshes/svh/collision/d11.obj" scale="1 1 1"/>
      </geometry>
    </collision>
  </link>
  <link name="right_hand_b">
    <visual>
      <geometry>
        <mesh filename="../meshes/svh/visual/d12.obj" scale="1 1 1"/>
      </geometry>
    </visual>
    <collision>
      <geometry>
        <mesh filename="../meshes/svh/collision/d12.obj" scale="1 1 1"/>
      </geometry>
    </collision>
  </link>
  <link name="right_hand_c">
    <inertial>
      <origin rpy="0 0 0" xyz="0.007 0.000 0.000"/>
      <mass value="0.02"/>
      <inertia ixx="1e-5" ixy="0.0" ixz="0.0" iyy="2e-5" iyz="0.0" izz="2e-5"/>
    </inertial>
    <visual>
      <geometry>
        <mesh filename="../meshes/svh/visual/d13.obj" scale="1 1 1"/>
      </geometry>
    </visual>
    <collision>
      <geometry>
        <mesh filename="../meshes/svh/collision/d13.obj" scale="1 1 1"/>
      </geometry>
    </collision>
  </link>
  <!-- INDEX FINGER LINKS -->
  <link name="right_hand_virtual_l">
    <visual>
      <origin xyz="0 0 0.01321"/>
      <geometry>
        <mesh filename="../meshes/svh/visual/f10_f20.obj"/>
      </geometry>
    </visual>
    <collision>
      <origin xyz="0 0 0.00121"/>
      <geometry>
        <sphere radius="0.01"/>
      </geometry>
    </collision>
  </link>
  <link name="right_hand_l">
    <visual>
      <geometry>
        <mesh filename="../meshes/svh/visual/f11.obj"/>
      </geometry>
    </visual>
    <collision>
      <geometry>
        <mesh filename="../meshes/svh/collision/f11.obj" scale="1 1 1"/>
      </geometry>
    </collision>
  </link>
  <link name="right_hand_p">
    <inertial>
      <origin rpy="0 0 0" xyz="0.01 0.000 0.000"/>
      <mass value="0.024"/>
      <inertia ixx="9e-7" ixy="0.0" ixz="0.0" iyy="3e-6" iyz="0.0" izz="2e-6"/>
    </inertial>
    <visual>
      <geometry>
        <mesh filename="../meshes/svh/visual/f12.obj"/>
      </geometry>
    </visual>
    <collision>
      <geometry>
        <mesh filename="../meshes/svh/collision/f12.obj"/>
      </geometry>
    </collision>
  </link>
  <link name="right_hand_t">
    <inertial>
      <origin rpy="0 0 0" xyz="0.007 0.000 0.000"/>
      <mass value="0.02"/>
      <inertia ixx="1e-5" ixy="0.0" ixz="0.0" iyy="2e-5" iyz="0.0" izz="2e-5"/>
    </inertial>
    <visual>
      <geometry>
        <mesh filename="../meshes/svh/visual/finger_tip.obj"/>
      </geometry>
    </visual>
    <collision>
      <geometry>
        <mesh filename="../meshes/svh/collision/finger_tip.obj" scale="1 1 1"/>
      </geometry>
    </collision>
  </link>
  <!-- MIDDLE FINGER LINKS -->
  <link name="right_hand_virtual_k">
    <visual>
      <origin xyz="0 0 0.01321"/>
      <geometry>
        <mesh filename="../meshes/svh/visual/f10_f20.obj"/>
      </geometry>
    </visual>
    <collision>
      <origin xyz="0 0 0.00321"/>
      <geometry>
        <sphere radius="0.01"/>
      </geometry>
    </collision>
  </link>
  <link name="right_hand_k">
    <visual>
      <geometry>
        <mesh filename="../meshes/svh/visual/f21.obj"/>
      </geometry>
    </visual>
    <collision>
      <geometry>
        <mesh filename="../meshes/svh/collision/f21.obj" scale="1 1 1"/>
      </geometry>
    </collision>
  </link>
  <link name="right_hand_o">
    <visual>
      <geometry>
        <mesh filename="../meshes/svh/visual/f22_f32.obj"/>
      </geometry>
    </visual>
    <collision>
      <geometry>
        <mesh filename="../meshes/svh/collision/f22_f32.obj" scale="1 1 1"/>
      </geometry>
    </collision>
  </link>
  <link name="right_hand_s">
    <inertial>
      <origin rpy="0 0 0" xyz="0.007 0.000 0.000"/>
      <mass value="0.02"/>
      <inertia ixx="1e-5" ixy="0.0" ixz="0.0" iyy="2e-5" iyz="0.0" izz="2e-5"/>
    </inertial>
    <visual>
      <geometry>
        <mesh filename="../meshes/svh/visual/finger_tip.obj"/>
      </geometry>
    </visual>
    <collision>
      <geometry>
        <mesh filename="../meshes/svh/collision/finger_tip.obj" scale="1 1 1"/>
      </geometry>
    </collision>
  </link>
  <!-- RING FINGER LINKS -->
  <link name="right_hand_virtual_j">
    <visual>
      <origin xyz="0 0 -0.01321"/>
      <geometry>
        <mesh filename="../meshes/svh/visual/f30_f40.obj"/>
      </geometry>
    </visual>
    <collision>
      <origin xyz="0 0 -0.00321"/>
      <geometry>
        <sphere radius="0.01"/>
      </geometry>
    </collision>
  </link>
  <link name="right_hand_j">
    <visual>
      <geometry>
        <mesh filename="../meshes/svh/visual/f31.obj"/>
      </geometry>
    </visual>
    <collision>
      <geometry>
        <mesh filename="../meshes/svh/collision/f31.obj" scale="1 1 1"/>
      </geometry>
    </collision>
  </link>
  <link name="right_hand_n">
    <visual>
      <geometry>
        <mesh filename="../meshes/svh/visual/f22_f32.obj"/>
      </geometry>
    </visual>
    <collision>
      <geometry>
        <mesh filename="../meshes/svh/collision/f22_f32.obj" scale="1 1 1"/>
      </geometry>
    </collision>
  </link>
  <link name="right_hand_r">
    <inertial>
      <origin rpy="0 0 0" xyz="0.007 0.000 0.000"/>
      <mass value="0.02"/>
      <inertia ixx="1e-5" ixy="0.0" ixz="0.0" iyy="2e-5" iyz="0.0" izz="2e-5"/>
    </inertial>
    <visual>
      <geometry>
        <mesh filename="../meshes/svh/visual/finger_tip.obj"/>
      </geometry>
    </visual>
    <collision>
      <geometry>
        <mesh filename="../meshes/svh/collision/finger_tip.obj" scale="1 1 1"/>
      </geometry>
    </collision>
  </link>
  <!-- LITTLE FINGER LINKS -->
  <link name="right_hand_virtual_i">
    <visual>
      <origin xyz="0 0 -0.01321"/>
      <geometry>
        <mesh filename="../meshes/svh/visual/f30_f40.obj"/>
      </geometry>
    </visual>
    <collision>
      <origin xyz="0 0 -0.00321"/>
      <geometry>
        <sphere radius="0.01"/>
      </geometry>
    </collision>
  </link>
  <link name="right_hand_i">
    <visual>
      <geometry>
        <mesh filename="../meshes/svh/visual/f41.obj"/>
      </geometry>
    </visual>
    <collision>
      <geometry>
        <mesh filename="../meshes/svh/collision/f41.obj"/>
      </geometry>
    </collision>
  </link>
  <link name="right_hand_m">
    <inertial>
      <origin rpy="0 0 0" xyz="0.007 0.000 0.000"/>
      <mass value="0.02"/>
      <inertia ixx="8e-7" ixy="0.0" ixz="0.0" iyy="2e-6" iyz="0.0" izz="2e-6"/>
    </inertial>
    <visual>
      <geometry>
        <mesh filename="../meshes/svh/visual/f42.obj"/>
      </geometry>
    </visual>
    <collision>
      <geometry>
        <mesh filename="../meshes/svh/collision/f42.obj"/>
      </geometry>
    </collision>
  </link>
  <link name="right_hand_q">
    <inertial>
      <origin rpy="0 0 0" xyz="0.007 0.000 0.000"/>
      <mass value="0.02"/>
      <inertia ixx="1e-5" ixy="0.0" ixz="0.0" iyy="2e-5" iyz="0.0" izz="2e-5"/>
    </inertial>
    <visual>
      <geometry>
        <mesh filename="../meshes/svh/visual/finger_tip.obj"/>
      </geometry>
    </visual>
    <collision>
      <geometry>
        <mesh filename="../meshes/svh/collision/finger_tip.obj"/>
      </geometry>
    </collision>
  </link>
  <joint name="right_hand_Thumb_Flexion" type="revolute">
    <parent link="right_hand_z"/>
    <child link="right_hand_a"/>
    <limit effort="1000.0" lower="0.0" upper="0.9704" velocity="1"/>
    <origin rpy="1.57079 -0.6004 1.57079" xyz="0 0 0.04596"/>
    <axis xyz="0 0 1"/>
  </joint>
  <!-- BASE_LINE JOINTS -->
  <joint name="right_hand_Thumb_Opposition" type="revolute">
    <parent link="right_hand_e1"/>
    <child link="right_hand_z"/>
    <limit effort="1000.0" lower="0.0" upper="0.9879" velocity="1"/>
    <origin rpy="0 0.2618 1.571" xyz="-0.0169 0.02626 0"/>
    <axis xyz="0 0 -1"/>
  </joint>
  <joint name="right_hand_f4" type="fixed">
    <parent link="right_hand_base_link"/>
    <child link="right_hand_e1"/>
    <origin rpy="0 0 0" xyz="0 -0.01313 0"/>
  </joint>
  <joint name="right_hand_j5" type="revolute">
    <parent link="right_hand_e1"/>
    <child link="right_hand_e2"/>
    <limit effort="1000.0" lower="0.0" upper="0.98786" velocity="1"/>
    <origin rpy="0 0 0" xyz="0.0184 0.006 0.0375"/>
    <axis xyz="0 0 1"/>
    <!--<mimic joint="right_hand_Thumb_Opposition" multiplier="1" offset="0"/>-->
  </joint>
  <!-- THUMB JOINTS -->
  <joint name="right_hand_j3" type="revolute">
    <parent link="right_hand_a"/>
    <child link="right_hand_b"/>
    <limit effort="1000.0" lower="0.0" upper="0.98506" velocity="1"/>
    <origin rpy="0 0 0" xyz="0.0485 0 0"/>
    <axis xyz="0 0 1"/>
    <!--<mimic joint="right_hand_Thumb_Flexion" multiplier="1.01511" offset="0"/>-->
  </joint>
  <joint name="right_hand_j4" type="revolute">
    <parent link="right_hand_b"/>
    <child link="right_hand_c"/>
    <limit effort="1000.0" lower="0.0" upper="1.406" velocity="1"/>
    <origin rpy="0 0 0" xyz="0.030 0 0"/>
    <axis xyz="0 0 1"/>
    <!--<mimic joint="right_hand_Thumb_Flexion" multiplier="1.44889" offset="0"/>-->
  </joint>
  <!-- INDEX FINGER JOINTS -->
  <joint name="right_hand_Index_Finger_Distal" type="revolute">
    <parent link="right_hand_l"/>
    <child link="right_hand_p"/>
    <limit effort="1000.0" lower="0" upper="1.334" velocity="1"/>
    <origin rpy="0 0 0" xyz="0.04804 0 0"/>
    <axis xyz="0 0 1"/>
  </joint>
  <joint name="right_hand_Index_Finger_Proximal" type="revolute">
    <parent link="right_hand_virtual_l"/>
    <child link="right_hand_l"/>
    <limit effort="1000.0" lower="0.0" upper="0.79849" velocity="1"/>
    <origin rpy="-1.5707 0 0" xyz="0 0 0"/>
    <axis xyz="0 0 1"/>
  </joint>
  <!-- JOINT Finger_Spread in BASE_LINE section for better UX -->
  <joint name="right_hand_j14" type="revolute">
    <parent link="right_hand_p"/>
    <child link="right_hand_t"/>
    <limit effort="1000.0" lower="0" upper="1.394" velocity="1"/>
    <origin rpy="0 0 0" xyz="0.026 0 0"/>
    <axis xyz="0 0 1"/>
    <!--<mimic joint="right_hand_Index_Finger_Distal" multiplier="1.0450" offset="0"/>-->
  </joint>
  <!-- MIDDLE FINGER JOINTS -->
  <joint name="right_hand_Middle_Finger_Proximal" type="revolute">
    <parent link="right_hand_virtual_k"/>
    <child link="right_hand_k"/>
    <limit effort="1000.0" lower="0.0" upper="0.79849" velocity="1"/>
    <origin rpy="-1.5707 0 0" xyz="0 0 0"/>
    <axis xyz="0 0 1"/>
  </joint>
  <joint name="right_hand_Middle_Finger_Distal" type="revolute">
    <parent link="right_hand_k"/>
    <child link="right_hand_o"/>
    <limit effort="1000.0" lower="0" upper="1.334" velocity="1"/>
    <origin rpy="0 0 0" xyz="0.05004 0 0"/>
    <axis xyz="0 0 1"/>
  </joint>
  <joint name="right_hand_j15" type="revolute">
    <parent link="right_hand_o"/>
    <child link="right_hand_s"/>
    <limit effort="1000.0" lower="0" upper="1.334" velocity="1"/>
    <origin rpy="0 0 0" xyz="0.032 0 0"/>
    <axis xyz="0 0 1"/>
    <!--<mimic joint="right_hand_Middle_Finger_Distal" multiplier="1.0454" offset="0"/>-->
  </joint>
  <!-- RING FINGER JOINTS -->
  <joint name="right_hand_Ring_Finger" type="revolute">
    <parent link="right_hand_virtual_j"/>
    <child link="right_hand_j"/>
    <limit effort="1000.0" lower="0.0" upper="0.98175" velocity="1"/>
    <origin rpy="1.5707 0 0" xyz="0 0 0"/>
    <axis xyz="0 0 1"/>
  </joint>
  <joint name="right_hand_j12" type="revolute">
    <parent link="right_hand_j"/>
    <child link="right_hand_n"/>
    <limit effort="1000.0" lower="0" upper="1.334" velocity="1"/>
    <origin rpy="0 0 0" xyz="0.05004 0 0"/>
    <axis xyz="0 0 1"/>
    <!--<mimic joint="right_hand_Ring_Finger" multiplier="1.3588" offset="0"/>-->
  </joint>
  <joint name="right_hand_j16" type="revolute">
    <parent link="right_hand_n"/>
    <child link="right_hand_r"/>
    <limit effort="1000.0" lower="0" upper="1.395" velocity="1"/>
    <origin rpy="0 0 0" xyz="0.032 0 0"/>
    <axis xyz="0 0 1"/>
    <!--<mimic joint="right_hand_Ring_Finger" multiplier="1.42093" offset="0"/>-->
  </joint>
  <!-- PINKY JOINTS -->
  <joint name="right_hand_Pinky" type="revolute">
    <parent link="right_hand_virtual_i"/>
    <child link="right_hand_i"/>
    <limit effort="1000.0" lower="0.0" upper="0.98175" velocity="1"/>
    <origin rpy="1.5707 0 0" xyz="0 0 0"/>
    <axis xyz="0 0 1"/>
  </joint>
  <joint name="right_hand_j13" type="revolute">
    <parent link="right_hand_i"/>
    <child link="right_hand_m"/>
    <limit effort="1000.0" lower="0" upper="1.334" velocity="1"/>
    <origin rpy="0 0 0" xyz="0.04454 0 0"/>
    <axis xyz="0 0 1"/>
    <!--<mimic joint="right_hand_Pinky" multiplier="1.35880" offset="0"/>-->
  </joint>
  <joint name="right_hand_j17" type="revolute">
    <parent link="right_hand_m"/>
    <child link="right_hand_q"/>
    <limit effort="1000.0" lower="0" upper="1.3971" velocity="1"/>
    <origin rpy="0 0 0" xyz="0.022 0 0"/>
    <axis xyz="0 0 1"/>
    <!--<mimic joint="right_hand_Pinky" multiplier="1.42307" offset="0"/>-->
  </joint>
  <joint name="right_hand_index_spread" type="revolute">
    <parent link="right_hand_e1"/>
    <child link="right_hand_virtual_l"/>
    <limit effort="1000.0" lower="0.0" upper="0.28833" velocity="1"/>
    <origin rpy="0 -1.5707 1.5707" xyz="-0.025 0 0.110"/>
    <axis xyz="0 0 1"/>
    <!--<mimic joint="right_hand_Finger_Spread" multiplier="0.5" offset="0"/>-->
  </joint>
  <joint name="right_hand_middle_spread_dummy" type="fixed">
    <parent link="right_hand_e1"/>
    <child link="right_hand_virtual_k"/>
    <origin rpy="0 -1.5707 1.5707" xyz="0 0 0.110"/>
  </joint>
  <joint name="right_hand_ring_spread" type="revolute">
    <parent link="right_hand_e2"/>
    <child link="right_hand_virtual_j"/>
    <limit effort="1000.0" lower="0.0" upper="0.28833" velocity="1"/>
    <origin rpy="-1.5707 -1.5707 0" xyz="0.003855 -0.006 0.0655"/>
    <axis xyz="0 0 1"/>
    <!--<mimic joint="right_hand_Finger_Spread" multiplier="0.5" offset="0"/>-->
  </joint>
  <joint name="right_hand_Finger_Spread" type="revolute">
    <parent link="right_hand_e2"/>
    <child link="right_hand_virtual_i"/>
    <limit effort="1000.0" lower="0.0" upper="0.5829" velocity="1"/>
    <origin rpy="-1.5707 -1.5707 0" xyz="0.025355 -0.006 0.056"/>
    <axis xyz="0 0 1"/>
  </joint>

  <link name="thtip"/>
  <link name="fftip"/>
  <link name="mftip"/>
  <link name="rftip"/>
  <link name="lftip"/>
  <joint name="thtip_joint" type="fixed">
    <parent link="right_hand_c"/>
    <child link="thtip"/>
    <origin rpy="0.00000 -0.00000 0.00000" xyz="0.0275 0.000 0.000"/>
  </joint>
  <joint name="fftip_joint" type="fixed">
    <parent link="right_hand_t"/>
    <child link="fftip"/>
    <origin rpy="0.00000 -0.00000 0.00000" xyz="0.014 0.000 0.000"/>
  </joint>
  <joint name="mftip_joint" type="fixed">
    <parent link="right_hand_s"/>
    <child link="mftip"/>
    <origin rpy="0.00000 -0.00000 0.00000" xyz="0.014 0.000 0.000"/>
  </joint>
  <joint name="rftip_joint" type="fixed">
    <parent link="right_hand_r"/>
    <child link="rftip"/>
    <origin rpy="0.00000 -0.00000 0.00000" xyz="0.014 0.000 0.000"/>
  </joint>
  <joint name="lftip_joint" type="fixed">
    <parent link="right_hand_q"/>
    <child link="lftip"/>
    <origin rpy="0.00000 -0.00000 0.00000" xyz="0.014 0.000 0.000"/>
  </joint>
</robot>

