<?xml version="1.0" encoding="utf-8"?>
<robot name="rm65_ability_right">
  <link name="arm_base_link">
    <inertial>
      <origin xyz="-0.000433277303987328 -3.54664423471128E-05 0.0599427668933796" rpy="0 0 0" />
      <mass value="0.841070778135659" />
      <inertia ixx="0.0017261110801622" ixy="2.52746264980217E-06" ixz="-3.67690303614961E-05"
        iyy="0.00170987405835604" iyz="1.67996364994424E-06" izz="0.000904023422915791" />
    </inertial>
    <visual>
      <origin xyz="0 0 0" rpy="0 0 0" />
      <geometry>
        <mesh filename="../meshes/rm65/rm65_base_link.stl" />
      </geometry>
      <material name="">
        <color rgba="1 1 1 1" />
      </material>
    </visual>
    <collision>
      <origin xyz="0 0 0" rpy="0 0 0" />
      <geometry>
        <mesh filename="../meshes/rm65/rm65_base_link.stl" />
      </geometry>
    </collision>
  </link>
  <link name="arm_link1">
    <inertial>
      <origin xyz="1.2226305431569E-08 0.0211079974844683 -0.0251854220842269" rpy="0 0 0" />
      <mass value="0.593563443690403" />
      <inertia ixx="0.00126614120341847" ixy="-1.294980943835E-08" ixz="-9.80120923066996E-09"
        iyy="0.00118168178300364" iyz="-0.00021121727444415" izz="0.00056135241627747" />
    </inertial>
    <visual>
      <origin xyz="0 0 0" rpy="0 0 0" />
      <geometry>
        <mesh filename="../meshes/rm65/rm65_link1.stl" />
      </geometry>
      <material name="">
        <color rgba="1 1 1 1" />
      </material>
    </visual>
    <collision>
      <origin xyz="0 0 0" rpy="0 0 0" />
      <geometry>
        <mesh filename="../meshes/rm65/rm65_link1.stl" />
      </geometry>
    </collision>
  </link>
  <joint name="arm_joint1" type="revolute">
    <origin xyz="0 0 0.2405" rpy="0 0 0" />
    <parent link="arm_base_link" />
    <child link="arm_link1" />
    <axis xyz="0 0 1" />
    <limit lower="-3.1" upper="3.1" effort="60" velocity="3.14" />
  </joint>
  <link name="arm_link2">
    <inertial>
      <origin xyz="0.152256463426163 4.75383656106654E-07 -0.00620260383607792" rpy="0 0 0" />
      <mass value="0.864175046869043" />
      <inertia ixx="0.00089150298478414" ixy="-2.23268489334765E-08" ixz="0.00156246461035015"
        iyy="0.00733754343083901" iyz="6.28110889329165E-09" izz="0.00697869103915473" />
    </inertial>
    <visual>
      <origin xyz="0 0 0" rpy="0 0 0" />
      <geometry>
        <mesh filename="../meshes/rm65/rm65_link2.stl" />
      </geometry>
      <material name="">
        <color rgba="1 1 1 1" />
      </material>
    </visual>
    <collision>
      <origin xyz="0 0 0" rpy="0 0 0" />
      <geometry>
        <mesh filename="../meshes/rm65/rm65_link2.stl" />
      </geometry>
    </collision>
  </link>
  <joint name="arm_joint2" type="revolute">
    <origin xyz="0 0 0" rpy="1.5708 -1.5708 0" />
    <parent link="arm_link1" />
    <child link="arm_link2" />
    <axis xyz="0 0 1" />
    <limit lower="-2.268" upper="2.268" effort="60" velocity="3.14" />
  </joint>
  <link name="arm_link3">
    <inertial>
      <origin xyz="5.05312670989961E-06 -0.0595925663694732 0.010569069212336" rpy="0 0 0" />
      <mass value="0.289633681624654" />
      <inertia ixx="0.00063737100450158" ixy="-7.05261293649751E-08" ixz="-3.86643272239426E-08"
        iyy="0.00015648388095025" iyz="-0.00014461035994916" izz="0.000614178164773085" />
    </inertial>
    <visual>
      <origin xyz="0 0 0" rpy="0 0 0" />
      <geometry>
        <mesh
          filename="../meshes/rm65/rm65_link3.stl" />
      </geometry>
      <material name="">
        <color rgba="1 1 1 1" />
      </material>
    </visual>
    <collision>
      <origin xyz="0 0 0" rpy="0 0 0" />
      <geometry>
        <mesh filename="../meshes/rm65/rm65_link3.stl" />
      </geometry>
    </collision>
  </link>
  <joint name="arm_joint3" type="revolute">
    <origin xyz="0.256 0 0" rpy="0 0 1.5708" />
    <parent link="arm_link2" />
    <child link="arm_link3" />
    <axis xyz="0 0 1" />
    <limit lower="-2.355" upper="2.355" effort="30" velocity="3.92" />
  </joint>
  <link name="arm_link4">
    <inertial>
      <origin xyz="1.15516617405898E-06 -0.0180424468598241 -0.0215394748352687" rpy="0 0 0" />
      <mass value="0.239419768320061" />
      <inertia ixx="0.000285938919722783" ixy="3.07101359163101E-09" ixz="-2.21994118981953E-09"
        iyy="0.000262727540304212" iyz="4.4236583260078E-05" izz="0.000119888082791859" />
    </inertial>
    <visual>
      <origin xyz="0 0 0" rpy="0 0 0" />
      <geometry>
        <mesh filename="../meshes/rm65/rm65_link4.stl" />
      </geometry>
      <material name="">
        <color rgba="1 1 1 1" />
      </material>
    </visual>
    <collision>
      <origin xyz="0 0 0" rpy="0 0 0" />
      <geometry>
        <mesh filename="../meshes/rm65/rm65_link4.stl" />
      </geometry>
    </collision>
  </link>
  <joint name="arm_joint4" type="revolute">
    <origin xyz="0 -0.21 0" rpy="1.5708 0 0" />
    <parent link="arm_link3" />
    <child link="arm_link4" />
    <axis xyz="0 0 1" />
    <limit lower="-3.1" upper="3.1" effort="10" velocity="3.92" />
  </joint>
  <link name="arm_link5">
    <inertial>
      <origin xyz="3.19794786262152E-06 -0.0593808368101458 0.00736804250989326" rpy="0 0 0" />
      <mass value="0.218799761431678" />
      <inertia ixx="0.000350540363914072" ixy="-3.41781619975602E-08" ixz="-1.77056457224373E-08"
        iyy="0.000104927867487581" iyz="-7.82431228461971E-05" izz="0.000334482418423629" />
    </inertial>
    <visual>
      <origin xyz="0 0 0" rpy="0 0 0" />
      <geometry>
        <mesh filename="../meshes/rm65/rm65_link5.stl" />
      </geometry>
      <material name="">
        <color rgba="1 1 1 1" />
      </material>
    </visual>
    <collision>
      <origin xyz="0 0 0" rpy="0 0 0" />
      <geometry>
        <mesh filename="../meshes/rm65/rm65_link5.stl" />
      </geometry>
    </collision>
  </link>
  <joint name="arm_joint5" type="revolute">
    <origin xyz="0 0 0" rpy="-1.5708 0 0" />
    <parent link="arm_link4" />
    <child link="arm_link5" />
    <axis xyz="0 0 1" />
    <limit lower="-2.233" upper="2.233" effort="10" velocity="3.92" />
  </joint>
  <link name="arm_link6">
    <inertial>
      <origin xyz="0.000714234511756999 -0.000396718732824521 -0.0126723660946126" rpy="0 0 0" />
      <mass value="0.0649018034311231" />
      <inertia ixx="2.02766547502765E-05" ixy="-1.32505200276849E-06" ixz="-2.5845091522508E-08"
        iyy="1.87986725225022E-05" iyz="3.39471452125439E-09" izz="3.17885459163081E-05" />
    </inertial>
    <visual>
      <origin xyz="0 0 0" rpy="0 0 0" />
      <geometry>
        <mesh filename="../meshes/rm65/rm65_link6.stl" />
      </geometry>
      <material name="">
        <color rgba="1 1 1 1" />
      </material>
    </visual>
    <collision>
      <origin xyz="0 0 0" rpy="0 0 0" />
      <geometry>
        <mesh filename="../meshes/rm65/rm65_link6.stl" />
      </geometry>
    </collision>
  </link>
  <joint name="arm_joint6" type="revolute">
    <origin xyz="0 -0.144 0" rpy="1.5708 0 0" />
    <parent link="arm_link5" />
    <child link="arm_link6" />
    <axis xyz="0 0 1" />
    <limit lower="-6.28" upper="6.28" effort="10" velocity="3.92" />
  </joint>


  <joint name="arm_hand_joint" type="fixed">
    <parent link="arm_link6" />
    <child link="base_link" />
    <origin xyz="0.035 0 0.02" rpy="0 -1.5708 0" />
  </joint>

  <link name="base_link"/>
  <joint name="base_joint" type="fixed">
    <parent link="base_link"/>
    <child link="base"/>
    <origin xyz="0 0 0" rpy="0 0 -1.57079"/>
  </joint>
  <link name="base">
    <visual name="wrist_mesh">
      <origin rpy="0 0 0" xyz="0 0 0"/>
      <geometry>
        <mesh filename="../meshes/ability/visual/wristmesh.obj"/>
      </geometry>
    </visual>
    <collision>
      <origin xyz="0 0 0" rpy="0 0 0"/>
      <geometry>
        <mesh filename="../meshes/ability/collision/wristmesh_C.obj"/>
      </geometry>
    </collision>
    <inertial>  <!-- the mass and inertia here are NOT correct -->
      <mass value="0.200"/>
      <inertia ixx="978.26e-6" ixy="87.34e-6" ixz="322.99e-6" iyy="1244.78e-6" iyz="244.74e-6" izz="456.22e-6"/>
      <origin xyz="22.41911e-3 -0.15798201e-3 -0.01319866e-3" rpy="0 0 0"/>
    </inertial>
  </link>
  <joint name="wrist2thumb" type="fixed">
    <parent link="base"/>
    <child link="thumb_base"/>
    <origin xyz="-24.0476665e-3 3.78124745e-3 32.32964923e-3" rpy="3.14148426 -0.08848813 -3.14036612"/>
  </joint>
  <link name="thumb_base">
    <inertial>
      <mass value="0.200"/>
      <inertia ixx="978.26e-6" ixy="87.34e-6" ixz="322.99e-6" iyy="1244.78e-6" iyz="244.74e-6" izz="456.22e-6"/>
      <origin xyz="22.41911e-3 -0.15798201e-3 -0.01319866e-3" rpy="0 0 0"/>
    </inertial>
    <visual name="palm_mesh">
      <origin rpy="0 0 0" xyz="0 0 0"/>
      <geometry>
        <mesh filename="../meshes/ability/visual/FB_palm_ref_MIR.obj"/>
      </geometry>
    </visual>
    <collision>                                  <!-- thumb_base -->
      <origin xyz="0 0 0" rpy="0 0 0"/>
      <geometry>
        <mesh filename="../meshes/ability/collision/FB_palm_ref_MIR.obj"/>
      </geometry>
    </collision>
  </link>
  <link name="thumb_L1">
    <inertial>
      <mass value="0.00268342"/>
      <inertia ixx="0.16931e-4" ixy="-0.076214e-4" ixz="-0.16959148e-4" iyy="0.77769934e-4" iyz="0.0156622e-4" izz="0.7249122e-4"/>
      <origin rpy="0 0 0" xyz="14.606e-3 -1.890854e-3 -3.1155356e-3"/>
    </inertial>
    <visual name="thumb_mesh_1">
      <origin xyz=" 27.8283501e-3 1.7436510745838653e-19 14.7507e-3 " rpy=" 1.832595714594045 -0.0 5.366520605522463e-18 "/>
      <geometry>
        <mesh filename="../meshes/ability/visual/thumb-F1-MIR.obj"/>
      </geometry>
    </visual>
    <collision>                            <!-- thumb_L1 -->
      <origin xyz="27.8283501e-3 1.7436510745838653e-19 14.7507e-3" rpy="1.832595714594045 -0.0 5.366520605522463e-18"/>
      <geometry>
        <mesh filename="../meshes/ability/collision/thumb-F1-MIR_C.obj"/>
      </geometry>
    </collision>
  </link>
  <link name="thumb_L2">
    <inertial>
      <mass value="0.0055"/>
      <inertia ixx="4.4789082e-4" ixy="4.4789082e-4" ixz="-0.62144934e-4" iyy="15.600996e-4" iyz="-0.07466143e-4" izz="17.908554e-4"/>
      <origin rpy="0 0 0" xyz="30.020522e-3 5.59476e-3 -4.1504356e-3"/>
    </inertial>
    <visual name="thumb_mesh_2">
      <origin xyz="65.18669e-3 23.34021e-3 3.93483e-3" rpy="-3.141592 0 0.343830"/>
      <geometry>
        <mesh filename="../meshes/ability/visual/thumb-F2.obj"/>
      </geometry>
    </visual>
    <collision>                            <!-- thumb_L2 -->
      <origin xyz="65.18669e-3 23.34021e-3 3.93483e-3" rpy="-3.141592 0 0.343830"/>
      <geometry>
        <mesh filename="../meshes/ability/collision/thumb-F2_C.obj"/>
      </geometry>
    </collision>
  </link>
  <joint name="thumb_q1" type="revolute">
    <parent link="thumb_base"/>
    <child link="thumb_L1"/>
    <origin xyz=" 0.0 0.0 0.0 " rpy=" 3.141592653589793 -0.0 -0.18884434641020664 "/>
    <axis xyz="0 0 1"/>
    <limit lower="-2.0943951" upper="0" effort="1.2" velocity="40.338888721"/>    <!-- angles in rad, efforts in N-m, velocity in rad/s -->
    <dynamics damping="0.001" friction="0.001"/>  <!-- Friction coefficient is not from quantitative measurement -->
  </joint>
  <joint name="thumb_q2" type="revolute">
    <parent link="thumb_L1"/>
    <child link="thumb_L2"/>
    <origin xyz=" 27.8283501e-3 1.7436510745838653e-19 14.7507e-3 " rpy=" 1.832595714594045 -0.0 5.366520605522463e-18 "/>
    <axis xyz="0 0 1"/>
    <limit lower="0" upper="2.0943951" effort="6.0" velocity="8.0677777442"/>    <!-- angles in rad, efforts in N-m, velocity in rad/s -->
    <dynamics damping="0.001" friction="0.001"/>  <!-- Friction coefficient is not from quantitative measurement -->
  </joint>
  <link name="thumb_tip"/>
  <joint name="thumb_tip_joint" type="fixed">
    <parent link="thumb_L2"/>
    <child link="thumb_tip"/>
    <origin rpy="0 0 0" xyz="0.065 0.016 0"/>
  </joint>
  <link name="index_L1">
    <inertial>
      <mass value="0.00635888"/>
      <inertia ixx="0.29766e-4" ixy="-0.06447133e-4" ixz="-0.00423315e-4" iyy="3.6947967e-4" iyz="0.00083028e-4" izz="3.8176336e-4"/>
      <origin xyz="22.41911e-3 -0.15798201e-3 -0.01319866e-3" rpy="0 0 0"/>
    </inertial>
    <visual name="index_mesh_1">
      <origin xyz="38.472723e-3 3.257695e-3 0.000000" rpy="0 0 0.084474"/>
      <geometry>
        <mesh filename="../meshes/ability/visual/idx-F1.obj"/>
      </geometry>
    </visual>
    <collision>                                  <!-- index_L1 -->
      <origin xyz="0.036 -0.00175 0" rpy="0 0 0"/>
      <geometry>
        <sphere radius="0.0085"/>
      </geometry>
    </collision>
    <collision>
      <origin xyz="0.019 -0.0045 0" rpy="0 0 0.0845"/>
      <geometry>
        <box size="0.028 0.012 0.016"/>
      </geometry>
    </collision>
    <collision>
      <origin xyz="0.018 0.006 0" rpy="0 0 0.0845"/>
      <geometry>
        <box size="0.02 0.01 0.016"/>
      </geometry>
    </collision>
    <collision>
      <origin xyz="-0.001 0 0.007" rpy="0 0 0.0845"/>
      <geometry>
        <box size="0.012 0.012 0.002"/>
      </geometry>
    </collision>
    <collision>
      <origin xyz="-0.001 0 -0.007" rpy="0 0 0.0845"/>
      <geometry>
        <box size="0.012 0.012 0.002"/>
      </geometry>
    </collision>
  </link>
  <link name="index_L2">
    <inertial>
      <mass value="0.00645"/>
      <inertia ixx="0.82671e-4" ixy="-1.08876e-4" ixz="-0.00037e-4" iyy="1.98028e-4" iyz="0.00081e-4" izz="2.64638e-4"/>
      <origin rpy="0 0 0" xyz="13.36818e-3 -8.75392e-3 -0.02886e-3"/>
    </inertial>
    <visual name="index_mesh_2">
      <origin rpy="0 0 0" xyz="9.1241e-3 0 0"/>
      <geometry>
        <mesh filename="../meshes/ability/visual/idx-F2.obj"/>
      </geometry>
    </visual>
    <collision>                            <!-- index_L2 -->
      <origin xyz="0 0 0" rpy="0 0 0"/>
      <geometry>
        <mesh filename="../meshes/ability/collision/idx-F2_C.obj"/>
      </geometry>
    </collision>
    <collision>
      <origin xyz="0.03 -0.016 0" rpy="0 0 0"/>
      <geometry>
        <sphere radius="0.007"/>
      </geometry>
    </collision>
  </link>
  <joint name="index_q1" type="revolute">
    <parent link="thumb_base"/>
    <child link="index_L1"/>
    <origin xyz=" 9.49e-3 -13.04e-3 -62.95e-3 " rpy=" -1.1595426535897932 1.284473 -1.0510016535897932 "/>
    <axis xyz="0 0 1"/>
    <limit lower="0" upper="2.0943951" effort="6.0" velocity="8.0677777442"/>    <!-- angles in rad, efforts in N-m, velocity in rad/s -->
    <dynamics damping="0.001" friction="0.001"/>  <!-- Friction coefficient is not from quantitative measurement -->
  </joint>
  <joint name="index_q2" type="revolute">
    <parent link="index_L1"/>
    <child link="index_L2"/>
    <origin xyz="38.472723e-3 3.257695e-3 0.000000e-3" rpy="0 0 0.084474"/>
    <axis xyz="0 0 1"/>
    <limit lower="0.0" upper="2.6586" effort="6.0" velocity="8.0677777442"/>    <!-- angles in rad, efforts in N-m, velocity in rad/s -->
    <dynamics damping="0.001" friction="0.001"/>  <!-- Friction coefficient is not from quantitative measurement -->
    <!--<mimic joint="index_q1" multiplier="1.05851325" offset="0.72349796"/>-->
  </joint>
  <link name="index_tip"/>
  <joint name="index_tip_joint" type="fixed">
    <parent link="index_L2"/>
    <child link="index_tip"/>
    <origin rpy="0 0 0" xyz="0.035  -0.018 0"/>
  </joint>
  <link name="middle_L1">
    <inertial>
      <mass value="0.00635888"/>
      <inertia ixx="0.29766e-4" ixy="-0.06447133e-4" ixz="-0.00423315e-4" iyy="3.6947967e-4" iyz="0.00083028e-4" izz="3.8176336e-4"/>
      <origin xyz="22.41911e-3 -0.15798201e-3 -0.01319866e-3" rpy="0 0 0"/>
    </inertial>
    <visual name="middle_mesh_1">
      <origin xyz="38.472723e-3 3.257695e-3 0.000000" rpy="0 0 0.084474"/>
      <geometry>
        <mesh filename="../meshes/ability/visual/idx-F1.obj"/>
      </geometry>
    </visual>
    <collision>                                  <!-- middle_L1 -->
      <origin xyz="0.036 -0.00175 0" rpy="0 0 0"/>
      <geometry>
        <sphere radius="0.0085"/>
      </geometry>
    </collision>
    <collision>
      <origin xyz="0.019 -0.0045 0" rpy="0 0 0.0845"/>
      <geometry>
        <box size="0.028 0.012 0.016"/>
      </geometry>
    </collision>
    <collision>
      <origin xyz="0.018 0.006 0" rpy="0 0 0.0845"/>
      <geometry>
        <box size="0.02 0.01 0.016"/>
      </geometry>
    </collision>
    <collision>
      <origin xyz="-0.001 0 0.007" rpy="0 0 0.0845"/>
      <geometry>
        <box size="0.012 0.012 0.002"/>
      </geometry>
    </collision>
    <collision>
      <origin xyz="-0.001 0 -0.007" rpy="0 0 0.0845"/>
      <geometry>
        <box size="0.012 0.012 0.002"/>
      </geometry>
    </collision>
  </link>
  <link name="middle_L2">
    <inertial>
      <mass value="0.00645"/>
      <inertia ixx="0.82671e-4" ixy="-1.08876e-4" ixz="-0.00037e-4" iyy="1.98028e-4" iyz="0.00081e-4" izz="2.64638e-4"/>
      <origin rpy="0 0 0" xyz="13.36818e-3 -8.75392e-3 -0.02886e-3"/>
    </inertial>
    <visual name="middle_mesh_2">
      <origin rpy="0 0 0" xyz="9.1241e-3 0 0"/>
      <geometry>
        <mesh filename="../meshes/ability/visual/idx-F2.obj"/>
      </geometry>
    </visual>
    <collision>                            <!-- middle_L2 -->
      <origin xyz="0 0 0" rpy="0 0 0"/>
      <geometry>
        <mesh filename="../meshes/ability/collision/idx-F2_C.obj"/>
      </geometry>
    </collision>
    <collision>
      <origin xyz="0.03 -0.016 0" rpy="0 0 0"/>
      <geometry>
        <sphere radius="0.007"/>
      </geometry>
    </collision>
  </link>
  <joint name="middle_q1" type="revolute">
    <parent link="thumb_base"/>
    <child link="middle_L1"/>
    <origin xyz=" -9.653191e-3 -15.310271e-3 -67.853949e-3 " rpy=" -1.2810616535897934 1.308458 -1.2453756535897933 "/>
    <limit lower="0" upper="2.0943951" effort="6.0" velocity="8.0677777442"/>    <!-- angles in rad, efforts in N-m, velocity in rad/s -->
    <dynamics damping="0.001" friction="0.001"/>  <!-- Friction coefficient is not from quantitative measurement -->
    <axis xyz="0 0 1"/>
  </joint>
  <joint name="middle_q2" type="revolute">
    <parent link="middle_L1"/>
    <child link="middle_L2"/>
    <origin xyz="38.472723e-3 3.257695e-3 0.000000" rpy="0 0 0.084474"/>
    <axis xyz="0 0 1"/>
    <limit lower="0.0" upper="2.6586" effort="6.0" velocity="8.0677777442"/>    <!-- angles in rad, efforts in N-m, velocity in rad/s -->
    <dynamics damping="0.001" friction="0.001"/>  <!-- Friction coefficient is not from quantitative measurement -->
    <!--<mimic joint="middle_q1" multiplier="1.05851325" offset="0.72349796"/>-->
  </joint>
  <link name="middle_tip"/>
  <joint name="middle_tip_joint" type="fixed">
    <parent link="middle_L2"/>
    <child link="middle_tip"/>
    <origin rpy="0 0 0" xyz="0.035  -0.018 0"/>
  </joint>
  <link name="ring_L1">
    <inertial>
      <mass value="0.00635888"/>
      <inertia ixx="0.29766e-4" ixy="-0.06447133e-4" ixz="-0.00423315e-4" iyy="3.6947967e-4" iyz="0.00083028e-4" izz="3.8176336e-4"/>
      <origin xyz="22.41911e-3 -0.15798201e-3 -0.01319866e-3" rpy="0 0 0"/>
    </inertial>
    <visual name="ring_mesh_1">
      <origin xyz="38.472723e-3 3.257695e-3 0.000000" rpy="0 0 0.084474"/>
      <geometry>
        <mesh filename="../meshes/ability/visual/idx-F1.obj"/>
      </geometry>
    </visual>
    <collision>                                  <!-- ring_L1 -->
      <origin xyz="0.036 -0.00175 0" rpy="0 0 0"/>
      <geometry>
        <sphere radius="0.0085"/>
      </geometry>
    </collision>
    <collision>
      <origin xyz="0.019 -0.0045 0" rpy="0 0 0.0845"/>
      <geometry>
        <box size="0.028 0.012 0.016"/>
      </geometry>
    </collision>
    <collision>
      <origin xyz="0.018 0.006 0" rpy="0 0 0.0845"/>
      <geometry>
        <box size="0.02 0.01 0.016"/>
      </geometry>
    </collision>
    <collision>
      <origin xyz="-0.001 0 0.007" rpy="0 0 0.0845"/>
      <geometry>
        <box size="0.012 0.012 0.002"/>
      </geometry>
    </collision>
    <collision>
      <origin xyz="-0.001 0 -0.007" rpy="0 0 0.0845"/>
      <geometry>
        <box size="0.012 0.012 0.002"/>
      </geometry>
    </collision>
  </link>
  <link name="ring_L2">
    <inertial>
      <mass value="0.00645"/>
      <inertia ixx="0.82671e-4" ixy="-1.08876e-4" ixz="-0.00037e-4" iyy="1.98028e-4" iyz="0.00081e-4" izz="2.64638e-4"/>
      <origin rpy="0 0 0" xyz="13.36818e-3 -8.75392e-3 -0.02886e-3"/>
    </inertial>
    <visual name="ring_mesh_2">
      <origin rpy="0 0 0" xyz="9.1241e-3 0 0"/>
      <geometry>
        <mesh filename="../meshes/ability/visual/idx-F2.obj"/>
      </geometry>
    </visual>
    <collision>                            <!-- ring_L2 -->
      <origin xyz="0 0 0" rpy="0 0 0"/>
      <geometry>
        <mesh filename="../meshes/ability/collision/idx-F2_C.obj"/>
      </geometry>
    </collision>
    <collision>
      <origin xyz="0.03 -0.016 0" rpy="0 0 0"/>
      <geometry>
        <sphere radius="0.007"/>
      </geometry>
    </collision>
  </link>
  <joint name="ring_q1" type="revolute">
    <parent link="thumb_base"/>
    <child link="ring_L1"/>
    <origin xyz=" -29.95426e-3 -14.212492e-3 -67.286105e-3 " rpy=" -1.424994653589793 1.321452 -1.4657306535897934 "/>
    <limit lower="0" upper="2.0943951" effort="6.0" velocity="8.0677777442"/>    <!-- angles in rad, efforts in N-m, velocity in rad/s -->
    <dynamics damping="0.001" friction="0.001"/>  <!-- Friction coefficient is not from quantitative measurement -->
    <axis xyz="0 0 1"/>
  </joint>
  <joint name="ring_q2" type="revolute">
    <parent link="ring_L1"/>
    <child link="ring_L2"/>
    <origin xyz="38.472723e-3 3.257695e-3 0.000000" rpy="0 0 0.084474"/>
    <axis xyz="0 0 1"/>
    <limit lower="0.0" upper="2.6586" effort="6.0" velocity="8.0677777442"/>    <!-- angles in rad, efforts in N-m, velocity in rad/s -->
    <dynamics damping="0.001" friction="0.001"/>  <!-- Friction coefficient is not from quantitative measurement -->
    <!--<mimic joint="ring_q1" multiplier="1.05851325" offset="0.72349796"/>-->
  </joint>
  <link name="ring_tip"/>
  <joint name="ring_tip_joint" type="fixed">
    <parent link="ring_L2"/>
    <child link="ring_tip"/>
    <origin rpy="0 0 0" xyz="0.035  -0.018 0"/>
  </joint>
  <link name="pinky_L1">
    <inertial>
      <mass value="0.00635888"/>
      <inertia ixx="0.29766e-4" ixy="-0.06447133e-4" ixz="-0.00423315e-4" iyy="3.6947967e-4" iyz="0.00083028e-4" izz="3.8176336e-4"/>
      <origin xyz="22.41911e-3 -0.15798201e-3 -0.01319866e-3" rpy="0 0 0"/>
    </inertial>
    <visual name="pinky_mesh_1">
      <origin xyz="38.472723e-3 3.257695e-3 0.000000" rpy="0 0 0.084474"/>
      <geometry>
        <mesh filename="../meshes/ability/visual/idx-F1.obj"/>
      </geometry>
    </visual>
    <collision>                                  <!-- pinky_L1 -->
      <origin xyz="0.036 -0.00175 0" rpy="0 0 0"/>
      <geometry>
        <sphere radius="0.0085"/>
      </geometry>
    </collision>
    <collision>
      <origin xyz="0.019 -0.0045 0" rpy="0 0 0.0845"/>
      <geometry>
        <box size="0.028 0.012 0.016"/>
      </geometry>
    </collision>
    <collision>
      <origin xyz="0.018 0.006 0" rpy="0 0 0.0845"/>
      <geometry>
        <box size="0.02 0.01 0.016"/>
      </geometry>
    </collision>
    <collision>
      <origin xyz="-0.001 0 0.007" rpy="0 0 0.0845"/>
      <geometry>
        <box size="0.012 0.012 0.002"/>
      </geometry>
    </collision>
    <collision>
      <origin xyz="-0.001 0 -0.007" rpy="0 0 0.0845"/>
      <geometry>
        <box size="0.012 0.012 0.002"/>
      </geometry>
    </collision>
  </link>
  <link name="pinky_L2">
    <inertial>
      <mass value="0.00645"/>
      <inertia ixx="0.82671e-4" ixy="-1.08876e-4" ixz="-0.00037e-4" iyy="1.98028e-4" iyz="0.00081e-4" izz="2.64638e-4"/>
      <origin rpy="0 0 0" xyz="13.36818e-3 -8.75392e-3 -0.02886e-3"/>
    </inertial>
    <visual name="pinky_mesh_2">
      <origin rpy="0 0 0" xyz="9.1241e-3 0 0"/>
      <geometry>
        <mesh filename="../meshes/ability/visual/idx-F2.obj"/>
      </geometry>
    </visual>
    <collision>                            <!-- pinky_L2 -->
      <origin xyz="0 0 0" rpy="0 0 0"/>
      <geometry>
        <mesh filename="../meshes/ability/collision/idx-F2_C.obj"/>
      </geometry>
    </collision>
    <collision>
      <origin xyz="0.03 -0.016 0" rpy="0 0 0"/>
      <geometry>
        <sphere radius="0.007"/>
      </geometry>
    </collision>
  </link>
  <joint name="pinky_q1" type="revolute">
    <parent link="thumb_base"/>
    <child link="pinky_L1"/>
    <origin xyz=" -49.521293e-3 -11.004583e-3 -63.029065e-3 " rpy=" -1.3764826535897934 1.32222 -1.4832096535897932 "/>
    <limit lower="0" upper="2.0943951" effort="6.0" velocity="8.0677777442"/>    <!-- angles in rad, efforts in N-m, velocity in rad/s -->
    <dynamics damping="0.001" friction="0.001"/>  <!-- Friction coefficient is not from quantitative measurement -->
    <axis xyz="0 0 1"/>
  </joint>
  <joint name="pinky_q2" type="revolute">
    <parent link="pinky_L1"/>
    <child link="pinky_L2"/>
    <origin xyz="38.472723e-3 3.257695e-3 0.000000" rpy="0 0 0.084474"/>
    <limit lower="0.0" upper="2.6586" effort="6.0" velocity="8.0677777442"/>    <!-- angles in rad, efforts in N-m, velocity in rad/s -->
    <dynamics damping="0.001" friction="0.001"/>  <!-- Friction coefficient is not from quantitative measurement -->
    <axis xyz="0 0 1"/>
    <!--<mimic joint="pinky_q1" multiplier="1.05851325" offset="0.72349796"/>-->
  </joint>
  <link name="pinky_tip"/>
  <joint name="pinky_tip_joint" type="fixed">
    <parent link="pinky_L2"/>
    <child link="pinky_tip"/>
    <origin rpy="0 0 0" xyz="0.035  -0.018 0"/>
  </joint>
</robot>
